Workbook

Sheet flock performance sheet
A2: BATCH NO | B2: DATE | C2: ī | D2: SHED NO | E2: BIRDS OPENING STOCK | F2: MORTALITY | G2: CULLS | H2: BIRDS CLOSING STOCK | I2: FEED CONSUMPTION | J2: EGG PRODUCTION | K2: EGG BREKAGE | L2: ACTUAL PRODUCTION % | M2: TARGET PRODUCTION | N2: DIFFRENCE IN PRODUCTION | O2: FEED PER BIRD | P2: REMARKS
A3: 21 | B3: 46245 | C3: =(QUOTIENT(ROW()-2,7)+1)&"."&MOD(ROW()-2,7)&" - day "&(MOD(ROW()-2,7)+1) -> 1.1 - day 2 | D3: 1 | E3: 13673 | F3: 5 | G3: 0 | H3: =SUM(E3-F3-G3) -> 13668 | I3: 1620 | J3: 12480 | K3: 0 | L3: =SUM(J3+K3)/H3*100 -> 91.308165 | M3: 93.2 | N3: =SUM(L3-M3) -> -1.8918349 | O3: =SUM(I3/H3)*1000 -> 118.52502 | P3: Auto adjust , - should shown in different colour
A4: 21 | B4: 46246 | C4: =(QUOTIENT(ROW()-2,7)+1)&"."&MOD(ROW()-2,7)&" - day "&(MOD(ROW()-2,7)+1) -> 1.2 - day 3 | D4: chi | E4: 13673 | F4: 4 | G4: 1 | H4: =SUM(E4-F4-G4) -> 13668 | I4: 1122 | J4: 16523 | K4: 0 | L4: =SUM(J4+K4)/H4*100 -> 120.88821 | M4: 93.2 | N4: =SUM(L4-M4) -> 27.688206 | O4: =SUM(I4/H4)*1000 -> 82.089552
B5: 46247 | C5: =(QUOTIENT(ROW()-2,7)+1)&"."&MOD(ROW()-2,7)&" - day "&(MOD(ROW()-2,7)+1) -> 1.3 - day 4 | E5: =H4 -> 13668 | F5: 8 | G5: 2 | H5: =SUM(E5-F5-G5) -> 13658 | I5: 1620 | J5: 13500 | K5: 5 | L5: =SUM(J5+K5)/H5*100 -> 98.879777 | M5: 93.2 | N5: =SUM(L5-M5) -> 5.6797774 | O5: =SUM(I5/H5)*1000 -> 118.6118
B6: 46248 | C6: =(QUOTIENT(ROW()-2,7)+1)&"."&MOD(ROW()-2,7)&" - day "&(MOD(ROW()-2,7)+1) -> 1.4 - day 5 | E6: =H5 -> 13658 | H6: =SUM(E6-F6-G6) -> 13658 | L6: =SUM(J6+K6)/H6*100 -> 0 | M6: 93.2 | N6: =SUM(L6-M6) -> -93.2 | O6: =SUM(I6/H6)*1000 -> 0
B7: 46249 | C7: =(QUOTIENT(ROW()-2,7)+1)&"."&MOD(ROW()-2,7)&" - day "&(MOD(ROW()-2,7)+1) -> 1.5 - day 6 | E7: =H6 -> 13658 | H7: =SUM(E7-F7-G7) -> 13658 | L7: =SUM(J7+K7)/H7*100 -> 0 | M7: 93.2 | N7: =SUM(L7-M7) -> -93.2 | O7: =SUM(I7/H7)*1000 -> 0
B8: 46250 | C8: =(QUOTIENT(ROW()-2,7)+1)&"."&MOD(ROW()-2,7)&" - day "&(MOD(ROW()-2,7)+1) -> 1.6 - day 7 | E8: =H7 -> 13658 | H8: =SUM(E8-F8-G8) -> 13658 | L8: =SUM(J8+K8)/H8*100 -> 0 | M8: 93.2 | N8: =SUM(L8-M8) -> -93.2 | O8: =SUM(I8/H8)*1000 -> 0
B9: 46251 | C9: =(QUOTIENT(ROW()-2,7)+1)&"."&MOD(ROW()-2,7)&" - day "&(MOD(ROW()-2,7)+1) -> 2.0 - day 1 | E9: =H8 -> 13658 | H9: =SUM(E9-F9-G9) -> 13658 | L9: =SUM(J9+K9)/H9*100 -> 0 | M9: 93.2 | N9: =SUM(L9-M9) -> -93.2 | O9: =SUM(I9/H9)*1000 -> 0
B10: 46252 | C10: =(QUOTIENT(ROW()-2,7)+1)&"."&MOD(ROW()-2,7)&" - day "&(MOD(ROW()-2,7)+1) -> 2.1 - day 2 | E10: =H9 -> 13658 | H10: =SUM(E10-F10-G10) -> 13658 | L10: =SUM(J10+K10)/H10*100 -> 0 | M10: 93.2 | N10: =SUM(L10-M10) -> -93.2 | O10: =SUM(I10/H10)*1000 -> 0
B11: 46253 | C11: =(QUOTIENT(ROW()-2,7)+1)&"."&MOD(ROW()-2,7)&" - day "&(MOD(ROW()-2,7)+1) -> 2.2 - day 3 | E11: =H10 -> 13658 | H11: =SUM(E11-F11-G11) -> 13658 | L11: =SUM(J11+K11)/H11*100 -> 0 | M11: 93.2 | N11: =SUM(L11-M11) -> -93.2 | O11: =SUM(I11/H11)*1000 -> 0
B12: 46254 | C12: =(QUOTIENT(ROW()-2,7)+1)&"."&MOD(ROW()-2,7)&" - day "&(MOD(ROW()-2,7)+1) -> 2.3 - day 4 | E12: =H11 -> 13658 | H12: =SUM(E12-F12-G12) -> 13658 | L12: =SUM(J12+K12)/H12*100 -> 0 | M12: 93.2 | N12: =SUM(L12-M12) -> -93.2 | O12: =SUM(I12/H12)*1000 -> 0
B13: 46255 | C13: =(QUOTIENT(ROW()-2,7)+1)&"."&MOD(ROW()-2,7)&" - day "&(MOD(ROW()-2,7)+1) -> 2.4 - day 5 | E13: =H12 -> 13658 | H13: =SUM(E13-F13-G13) -> 13658 | L13: =SUM(J13+K13)/H13*100 -> 0 | M13: 93.2 | N13: =SUM(L13-M13) -> -93.2 | O13: =SUM(I13/H13)*1000 -> 0
B14: 46256 | C14: =(QUOTIENT(ROW()-2,7)+1)&"."&MOD(ROW()-2,7)&" - day "&(MOD(ROW()-2,7)+1) -> 2.5 - day 6 | E14: =H13 -> 13658 | H14: =SUM(E14-F14-G14) -> 13658 | L14: =SUM(J14+K14)/H14*100 -> 0 | M14: 93.2 | N14: =SUM(L14-M14) -> -93.2 | O14: =SUM(I14/H14)*1000 -> 0
B15: 46257 | C15: =(QUOTIENT(ROW()-2,7)+1)&"."&MOD(ROW()-2,7)&" - day "&(MOD(ROW()-2,7)+1) -> 2.6 - day 7 | E15: =H14 -> 13658 | H15: =SUM(E15-F15-G15) -> 13658 | L15: =SUM(J15+K15)/H15*100 -> 0 | M15: 93.2 | N15: =SUM(L15-M15) -> -93.2 | O15: =SUM(I15/H15)*1000 -> 0
B16: 46258 | C16: =(QUOTIENT(ROW()-2,7)+1)&"."&MOD(ROW()-2,7)&" - day "&(MOD(ROW()-2,7)+1) -> 3.0 - day 1 | E16: =H15 -> 13658 | H16: =SUM(E16-F16-G16) -> 13658 | L16: =SUM(J16+K16)/H16*100 -> 0 | M16: 93.2 | N16: =SUM(L16-M16) -> -93.2 | O16: =SUM(I16/H16)*1000 -> 0
B17: 46259 | C17: =(QUOTIENT(ROW()-2,7)+1)&"."&MOD(ROW()-2,7)&" - day "&(MOD(ROW()-2,7)+1) -> 3.1 - day 2 | E17: =H16 -> 13658 | H17: =SUM(E17-F17-G17) -> 13658 | L17: =SUM(J17+K17)/H17*100 -> 0 | M17: 93.2 | N17: =SUM(L17-M17) -> -93.2 | O17: =SUM(I17/H17)*1000 -> 0
... B20: 46262 | C20: =(QUOTIENT(ROW()-2,7)+1)&"."&MOD(ROW()-2,7)&" - day "&(MOD(ROW()-2,7)+1) -> 3.4 - day 5 | E20: =H19 -> 13658 | H20: =SUM(E20-F20-G20) -> 13658 | L20: =SUM(J20+K20)/H20*100 -> 0 | M20: 93.2 | N20: =SUM(L20-M20) -> -93.2 | O20: =SUM(I20/H20)*1000 -> 0
B21: 46263 | C21: =(QUOTIENT(ROW()-2,7)+1)&"."&MOD(ROW()-2,7)&" - day "&(MOD(ROW()-2,7)+1) -> 3.5 - day 6 | E21: =H20 -> 13658 | H21: =SUM(E21-F21-G21) -> 13658 | L21: =SUM(J21+K21)/H21*100 -> 0 | N21: =SUM(L21-M21) -> 0 | O21: =SUM(I21/H21)*1000 -> 0
B22: 46264 | C22: =(QUOTIENT(ROW()-2,7)+1)&"."&MOD(ROW()-2,7)&" - day "&(MOD(ROW()-2,7)+1) -> 3.6 - day 7 | E22: =H21 -> 13658 | H22: =SUM(E22-F22-G22) -> 13658 | L22: =SUM(J22+K22)/H22*100 -> 0 | N22: =SUM(L22-M22) -> 0 | O22: =SUM(I22/H22)*1000 -> 0
B23: 46265 | C23: =(QUOTIENT(ROW()-2,7)+1)&"."&MOD(ROW()-2,7)&" - day "&(MOD(ROW()-2,7)+1) -> 4.0 - day 1 | E23: =H22 -> 13658 | H23: =SUM(E23-F23-G23) -> 13658 | L23: =SUM(J23+K23)/H23*100 -> 0 | N23: =SUM(L23-M23) -> 0 | O23: =SUM(I23/H23)*1000 -> 0
B24: 46266 | C24: =(QUOTIENT(ROW()-2,7)+1)&"."&MOD(ROW()-2,7)&" - day "&(MOD(ROW()-2,7)+1) -> 4.1 - day 2 | E24: =H23 -> 13658 | H24: =SUM(E24-F24-G24) -> 13658 | L24: =SUM(J24+K24)/H24*100 -> 0 | N24: =SUM(L24-M24) -> 0 | O24: =SUM(I24/H24)*1000 -> 0
B25: 46267 | C25: =(QUOTIENT(ROW()-2,7)+1)&"."&MOD(ROW()-2,7)&" - day "&(MOD(ROW()-2,7)+1) -> 4.2 - day 3 | E25: =H24 -> 13658 | H25: =SUM(E25-F25-G25) -> 13658 | L25: =SUM(J25+K25)/H25*100 -> 0 | N25: =SUM(L25-M25) -> 0 | O25: =SUM(I25/H25)*1000 -> 0
B26: 46268 | C26: =(QUOTIENT(ROW()-2,7)+1)&"."&MOD(ROW()-2,7)&" - day "&(MOD(ROW()-2,7)+1) -> 4.3 - day 4 | E26: =H25 -> 13658 | H26: =SUM(E26-F26-G26) -> 13658 | L26: =SUM(J26+K26)/H26*100 -> 0 | N26: =SUM(L26-M26) -> 0 | O26: =SUM(I26/H26)*1000 -> 0
B27: 46269 | C27: =(QUOTIENT(ROW()-2,7)+1)&"."&MOD(ROW()-2,7)&" - day "&(MOD(ROW()-2,7)+1) -> 4.4 - day 5 | E27: =H26 -> 13658 | H27: =SUM(E27-F27-G27) -> 13658 | L27: =SUM(J27+K27)/H27*100 -> 0 | N27: =SUM(L27-M27) -> 0 | O27: =SUM(I27/H27)*1000 -> 0
B28: 46270 | C28: =(QUOTIENT(ROW()-2,7)+1)&"."&MOD(ROW()-2,7)&" - day "&(MOD(ROW()-2,7)+1) -> 4.5 - day 6 | E28: =H27 -> 13658 | H28: =SUM(E28-F28-G28) -> 13658 | L28: =SUM(J28+K28)/H28*100 -> 0 | N28: =SUM(L28-M28) -> 0 | O28: =SUM(I28/H28)*1000 -> 0
B29: 46271 | C29: =(QUOTIENT(ROW()-2,7)+1)&"."&MOD(ROW()-2,7)&" - day "&(MOD(ROW()-2,7)+1) -> 4.6 - day 7 | E29: =H28 -> 13658 | H29: =SUM(E29-F29-G29) -> 13658 | L29: =SUM(J29+K29)/H29*100 -> 0 | N29: =SUM(L29-M29) -> 0 | O29: =SUM(I29/H29)*1000 -> 0
B30: 46272 | C30: =(QUOTIENT(ROW()-2,7)+1)&"."&MOD(ROW()-2,7)&" - day "&(MOD(ROW()-2,7)+1) -> 5.0 - day 1 | E30: =H29 -> 13658 | H30: =SUM(E30-F30-G30) -> 13658 | L30: =SUM(J30+K30)/H30*100 -> 0 | N30: =SUM(L30-M30) -> 0 | O30: =SUM(I30/H30)*1000 -> 0
B31: 46273 | C31: =(QUOTIENT(ROW()-2,7)+1)&"."&MOD(ROW()-2,7)&" - day "&(MOD(ROW()-2,7)+1) -> 5.1 - day 2 | E31: =H30 -> 13658 | H31: =SUM(E31-F31-G31) -> 13658 | L31: =SUM(J31+K31)/H31*100 -> 0 | N31: =SUM(L31-M31) -> 0 | O31: =SUM(I31/H31)*1000 -> 0
B32: 46274 | C32: =(QUOTIENT(ROW()-2,7)+1)&"."&MOD(ROW()-2,7)&" - day "&(MOD(ROW()-2,7)+1) -> 5.2 - day 3 | E32: =H31 -> 13658 | H32: =SUM(E32-F32-G32) -> 13658 | L32: =SUM(J32+K32)/H32*100 -> 0 | N32: =SUM(L32-M32) -> 0 | O32: =SUM(I32/H32)*1000 -> 0
... B128: 46370 | C128: =(QUOTIENT(ROW()-2,7)+1)&"."&MOD(ROW()-2,7)&" - day "&(MOD(ROW()-2,7)+1) -> 19.0 - day 1 | E128: =H127 -> 13658 | H128: =SUM(E128-F128-G128) -> 13658 | L128: =SUM(J128+K128)/H128*100 -> 0 | N128: =SUM(L128-M128) -> 0 | O128: =SUM(I128/H128)*1000 -> 0
B129: 46371 | C129: =(QUOTIENT(ROW()-2,7)+1)&"."&MOD(ROW()-2,7)&" - day "&(MOD(ROW()-2,7)+1) -> 19.1 - day 2 | E129: =H128 -> 13658 | F129: 6 | G129: 1 | H129: =SUM(E129-F129-G129) -> 13651 | J129: 600 | K129: 5 | L129: =SUM(J129+K129)/H129*100 -> 4.4319098 | N129: =SUM(L129-M129) -> 4.4319098 | O129: =SUM(I129/H129)*1000 -> 0
B130: 46372 | C130: =(QUOTIENT(ROW()-2,7)+1)&"."&MOD(ROW()-2,7)&" - day "&(MOD(ROW()-2,7)+1) -> 19.2 - day 3 | E130: =H129 -> 13651 | F130: 13 | G130: 0 | H130: =SUM(E130-F130-G130) -> 13638 | J130: 800 | K130: 9 | L130: =SUM(J130+K130)/H130*100 -> 5.9319548 | N130: =SUM(L130-M130) -> 5.9319548 | O130: =SUM(I130/H130)*1000 -> 0
B131: 46373 | C131: =(QUOTIENT(ROW()-2,7)+1)&"."&MOD(ROW()-2,7)&" - day "&(MOD(ROW()-2,7)+1) -> 19.3 - day 4 | E131: =H130 -> 13638 | F131: 34 | G131: 0 | H131: =SUM(E131-F131-G131) -> 13604 | J131: 1500 | K131: 16 | L131: =SUM(J131+K131)/H131*100 -> 11.143781 | N131: =SUM(L131-M131) -> 11.143781 | O131: =SUM(I131/H131)*1000 -> 0
B132: 46374 | C132: =(QUOTIENT(ROW()-2,7)+1)&"."&MOD(ROW()-2,7)&" - day "&(MOD(ROW()-2,7)+1) -> 19.4 - day 5 | E132: =H131 -> 13604 | F132: 54 | G132: 0 | H132: =SUM(E132-F132-G132) -> 13550 | J132: 2344 | K132: 3 | L132: =SUM(J132+K132)/H132*100 -> 17.321033 | N132: =SUM(L132-M132) -> 17.321033 | O132: =SUM(I132/H132)*1000 -> 0
B133: 46375 | C133: =(QUOTIENT(ROW()-2,7)+1)&"."&MOD(ROW()-2,7)&" - day "&(MOD(ROW()-2,7)+1) -> 19.5 - day 6 | E133: =H132 -> 13550 | F133: 23 | G133: 0 | H133: =SUM(E133-F133-G133) -> 13527 | J133: 3234 | K133: 1 | L133: =SUM(J133+K133)/H133*100 -> 23.915133 | N133: =SUM(L133-M133) -> 23.915133 | O133: =SUM(I133/H133)*1000 -> 0
B134: 46376 | C134: =(QUOTIENT(ROW()-2,7)+1)&"."&MOD(ROW()-2,7)&" - day "&(MOD(ROW()-2,7)+1) -> 19.6 - day 7 | E134: =H133 -> 13527 | F134: 34 | G134: 0 | H134: =SUM(E134-F134-G134) -> 13493 | J134: 4322 | K134: 0 | L134: =SUM(J134+K134)/H134*100 -> 32.031424 | N134: =SUM(L134-M134) -> 32.031424 | O134: =SUM(I134/H134)*1000 -> 0
B135: 46377 | C135: =(QUOTIENT(ROW()-2,7)+1)&"."&MOD(ROW()-2,7)&" - day "&(MOD(ROW()-2,7)+1) -> 20.0 - day 1 | E135: =H134 -> 13493 | F135: 54 | G135: 3 | H135: =SUM(E135-F135-G135) -> 13436 | J135: 2344 | K135: 0 | L135: =SUM(J135+K135)/H135*100 -> 17.445668 | N135: =SUM(L135-M135) -> 17.445668 | O135: =SUM(I135/H135)*1000 -> 0
B136: 46378 | C136: =(QUOTIENT(ROW()-2,7)+1)&"."&MOD(ROW()-2,7)&" - day "&(MOD(ROW()-2,7)+1) -> 20.1 - day 2 | E136: =H135 -> 13436 | G136: 0 | H136: =SUM(E136-F136-G136) -> 13436 | L136: =SUM(J136+K136)/H136*100 -> 0 | N136: =SUM(L136-M136) -> 0 | O136: =SUM(I136/H136)*1000 -> 0
B137: 46379 | C137: =(QUOTIENT(ROW()-2,7)+1)&"."&MOD(ROW()-2,7)&" - day "&(MOD(ROW()-2,7)+1) -> 20.2 - day 3 | E137: =H136 -> 13436 | H137: =SUM(E137-F137-G137) -> 13436 | L137: =SUM(J137+K137)/H137*100 -> 0 | N137: =SUM(L137-M137) -> 0 | O137: =SUM(I137/H137)*1000 -> 0
B138: 46380 | C138: =(QUOTIENT(ROW()-2,7)+1)&"."&MOD(ROW()-2,7)&" - day "&(MOD(ROW()-2,7)+1) -> 20.3 - day 4 | E138: =H137 -> 13436 | H138: =SUM(E138-F138-G138) -> 13436 | L138: =SUM(J138+K138)/H138*100 -> 0 | N138: =SUM(L138-M138) -> 0 | O138: =SUM(I138/H138)*1000 -> 0
...

Sheet Sheet3
A3: BATCH NO | B3: DATE | C3: AGE OF THE BIRD | D3: SHED NO | E3: BIRDS OPENING STOCK | F3: MORTALITY | G3: CULLS | H3: BIRDS CLOSING STOCK | I3: FEED CONSUMPTION | J3: EGG PRODUCTION | K3: EGG BREKAGE | L3: ACTUAL PRODUCTION % | M3: TARGET PRODUCTION | N3: DIFFRENCE IN PRODUCTION | O3: FEED PER BIRD | P3: REMARKS
C4: 0.1 | D4: CHICK SHED
C5: 0.2
C6: 0.3
C7: 0.4
C8: 0.5
C9: 0.6
C10: 0.7
C11: 1 ST WEEK 1.1
C12: 1.2
C13: 1.3
C14: 1.4
C15: 1.5
C16: 1.6
C17: 1.7
C18: 2 ND WEEK 2.1
C19: 2.2
C20: 2.3
C21: 2.4
C22: 2.5
C23: 2.6
C24: 2.7
C25: 3RD WEEK 3.1
C26: 3.2
C27: 3.3
C28: 3.4
C29: 3.5
C30: 3.6
C31: 3.7
C32: 4TH WEEK 4.1
C33: 4.2
C34: 4.3
C35: 4.4
C36: 4.5
C37: 4.6
C38: 4.7

Sheet Sheet4
L1: BV 300 BREAD
C2: bovans bread | K2: AGE | L2: TARGET PRODUCTION
C3: target production depends on age | D3: target production | K3: 18 th week
C4: 18 th week | D4: 0.03 | K4: 19 th week | L4: 25
C5: 19th week | D5: 0.15 | K5: 20 th week | L5: 50
C6: 20th week | D6: 0.445 | K6: 21 th week | L6: 75
C7: 21st week | D7: 0.676 | K7: 22 th week | L7: 90
C8: 22nd week | D8: 0.824 | K8: 23 th week | L8: 93
C9: 23rd week | D9: 0.911 | K9: 24 th week | L9: 95
C10: 24th week | D10: 0.948 | K10: 25 th week | L10: 96
C11: 25th week | D11: 0.956 | K11: 26 th week | L11: 96.5
C12: 26th week | D12: 0.961 | K12: 27 th week | L12: 97
C13: 27th week | D13: 0.964 | K13: 28 th week | L13: 97.5
C14: 28th week | D14: 0.966 | K14: 29 th week | L14: 98
C15: 29th week | D15: 0.967 | K15: 30 th week | L15: 98
... C85: 99th week | D85: 0.77 | K85: 100 th week | L85: 75.3
C86: 100th week | D86: 0.77

Sheet Sheet1
A2: SUNRISE EGG FARMS BOVANS | E2: SHED NO: GL1-3 | G2: HEN HOUSED | I2: 16000
A3: Age | B3: No of birds | C3: Wkly depletion | D3: Depletion % | E3: Cum Depletion | F3: Weekly eggs | G3: HDP % | H3: HHP | I3: Cum HHP
A4: 19 | B4: 30000 | C4: {=SUM('flock performance sheet'!F129:F135+'flock performance sheet'!G129:G135)} -> 222 | D4: =C4/B4% -> 0.74 | E4: =D4 -> 0.74 | F4: {=SUM('flock performance sheet'!J129:J135+'flock performance sheet'!K129:K135)} -> 15178 | G4: =(F4/B4%)/7 -> 7.227619 | H4: =F4/B4 -> 0.50593333 | I4: =H4 -> 0.50593333 | K4: MORTALITY | L4: culls from fps sheet
A5: 20 | B5: =B4-C4 -> 29778 | C5: {=SUM('flock performance sheet'!F136:F142+'flock performance sheet'!G136:G142)} -> 0 | D5: =C5/B5% -> 0 | E5: =E4+D5 -> 0.74 | F5: {=SUM('flock performance sheet'!J136:J142+'flock performance sheet'!K136:K142)} -> 0 | G5: =(F5/B5%)/7 -> 0 | H5: =F5/B4 -> 0 | I5: =I4+H5 -> 0.50593333 | K5: egg production + breakage
A6: 21 | B6: =B5-C5 -> 29778 | C6: {=SUM('flock performance sheet'!F143:F149+'flock performance sheet'!G143:G149)} -> 0 | D6: =C6/B6% -> 0 | E6: =E5+D6 -> 0.74 | F6: {=SUM('flock performance sheet'!J143:J149+'flock performance sheet'!K143:K149)} -> 0 | G6: =(F6/B6%)/7 -> 0 | H6: =F6/B4 -> 0 | I6: =I5+H6 -> 0.50593333
A7: 22 | B7: =B6-C6 -> 29778 | C7: {=SUM('flock performance sheet'!F150:F156+'flock performance sheet'!G150:G156)} -> 0 | D7: =C7/B7% -> 0 | E7: =E6+D7 -> 0.74 | F7: {=SUM('flock performance sheet'!J150:J156+'flock performance sheet'!K150:K156)} -> 0 | G7: =(F7/B7%)/7 -> 0 | H7: =F7/B4 -> 0 | I7: =I6+H7 -> 0.50593333
A8: 23 | B8: =B7-C7 -> 29778 | C8: {=SUM('flock performance sheet'!F157:F163+'flock performance sheet'!G157:G163)} -> 0 | D8: =C8/B8% -> 0 | E8: =E7+D8 -> 0.74 | F8: {=SUM('flock performance sheet'!J157:J163+'flock performance sheet'!K157:K163)} -> 0 | G8: =(F8/B8%)/7 -> 0 | H8: =F8/B4 -> 0 | I8: =I7+H8 -> 0.50593333
A9: 24 | B9: =B8-C8 -> 29778 | C9: {=SUM('flock performance sheet'!F164:F170+'flock performance sheet'!G164:G170)} -> 0 | D9: =C9/B9% -> 0 | E9: =E8+D9 -> 0.74 | F9: {=SUM('flock performance sheet'!J164:J170+'flock performance sheet'!K164:K170)} -> 0 | G9: =(F9/B9%)/7 -> 0 | H9: =F9/B4 -> 0 | I9: =I8+H9 -> 0.50593333
A10: 25 | B10: =B9-C9 -> 29778 | C10: {=SUM('flock performance sheet'!F171:F177+'flock performance sheet'!G171:G177)} -> 0 | D10: =C10/B10% -> 0 | E10: =E9+D10 -> 0.74 | F10: {=SUM('flock performance sheet'!J171:J177+'flock performance sheet'!K171:K177)} -> 0 | G10: =(F10/B10%)/7 -> 0 | H10: =F10/B4 -> 0 | I10: =I9+H10 -> 0.50593333
A11: 26 | B11: =B10-C10 -> 29778 | C11: {=SUM('flock performance sheet'!F178:F184+'flock performance sheet'!G178:G184)} -> 0 | D11: =C11/B11% -> 0 | E11: =E10+D11 -> 0.74 | F11: {=SUM('flock performance sheet'!J178:J184+'flock performance sheet'!K178:K184)} -> 0 | G11: =(F11/B11%)/7 -> 0 | H11: =F11/B4 -> 0 | I11: =I10+H11 -> 0.50593333
A12: 27 | B12: =B11-C11 -> 29778 | C12: {=SUM('flock performance sheet'!F185:F191+'flock performance sheet'!G185:G191)} -> 0 | D12: =C12/B12% -> 0 | E12: =E11+D12 -> 0.74 | F12: {=SUM('flock performance sheet'!J185:J191+'flock performance sheet'!K185:K191)} -> 0 | G12: =(F12/B12%)/7 -> 0 | H12: =F12/B4 -> 0 | I12: =I11+H12 -> 0.50593333
A13: 28 | B13: =B12-C12 -> 29778 | C13: {=SUM('flock performance sheet'!F192:F198+'flock performance sheet'!G192:G198)} -> 0 | D13: =C13/B13% -> 0 | E13: =E12+D13 -> 0.74 | F13: {=SUM('flock performance sheet'!J192:J198+'flock performance sheet'!K192:K198)} -> 0 | G13: =(F13/B13%)/7 -> 0 | H13: =F13/B4 -> 0 | I13: =I12+H13 -> 0.50593333
A14: 29 | B14: =B13-C13 -> 29778 | C14: {=SUM('flock performance sheet'!F199:F205+'flock performance sheet'!G199:G205)} -> 0 | D14: =C14/B14% -> 0 | E14: =E13+D14 -> 0.74 | F14: {=SUM('flock performance sheet'!J199:J205+'flock performance sheet'!K199:K205)} -> 0 | G14: =(F14/B14%)/7 -> 0 | H14: =F14/B4 -> 0 | I14: =I13+H14 -> 0.50593333
A15: 30 | B15: =B14-C14 -> 29778 | C15: {=SUM('flock performance sheet'!F206:F212+'flock performance sheet'!G206:G212)} -> 0 | D15: =C15/B15% -> 0 | E15: =E14+D15 -> 0.74 | F15: {=SUM('flock performance sheet'!J206:J212+'flock performance sheet'!K206:K212)} -> 0 | G15: =(F15/B15%)/7 -> 0 | H15: =F15/B4 -> 0 | I15: =I14+H15 -> 0.50593333
A16: 31 | B16: =B15-C15 -> 29778 | C16: {=SUM('flock performance sheet'!F213:F219+'flock performance sheet'!G213:G219)} -> 0 | D16: =C16/B16% -> 0 | E16: =E15+D16 -> 0.74 | F16: {=SUM('flock performance sheet'!J213:J219+'flock performance sheet'!K213:K219)} -> 0 | G16: =(F16/B16%)/7 -> 0 | H16: =F16/B4 -> 0 | I16: =I15+H16 -> 0.50593333
A17: 32 | B17: =B16-C16 -> 29778 | C17: {=SUM('flock performance sheet'!F220:F226+'flock performance sheet'!G220:G226)} -> 0 | D17: =C17/B17% -> 0 | E17: =E16+D17 -> 0.74 | F17: {=SUM('flock performance sheet'!J220:J226+'flock performance sheet'!K220:K226)} -> 0 | G17: =(F17/B17%)/7 -> 0 | H17: =F17/B4 -> 0 | I17: =I16+H17 -> 0.50593333
A18: 33 | B18: =B17-C17 -> 29778 | C18: {=SUM('flock performance sheet'!F227:F233+'flock performance sheet'!G227:G233)} -> 0 | D18: =C18/B18% -> 0 | E18: =E17+D18 -> 0.74 | F18: {=SUM('flock performance sheet'!J227:J233+'flock performance sheet'!K227:K233)} -> 0 | G18: =(F18/B18%)/7 -> 0 | H18: =F18/B4 -> 0 | I18: =I17+H18 -> 0.50593333
A19: 34 | B19: =B18-C18 -> 29778 | C19: {=SUM('flock performance sheet'!F234:F240+'flock performance sheet'!G234:G240)} -> 0 | D19: =C19/B19% -> 0 | E19: =E18+D19 -> 0.74 | F19: {=SUM('flock performance sheet'!J234:J240+'flock performance sheet'!K234:K240)} -> 0 | G19: =(F19/B19%)/7 -> 0 | H19: =F19/B4 -> 0 | I19: =I18+H19 -> 0.50593333
A20: 35 | B20: =B19-C19 -> 29778 | C20: {=SUM('flock performance sheet'!F241:F247+'flock performance sheet'!G241:G247)} -> 0 | D20: =C20/B20% -> 0 | E20: =E19+D20 -> 0.74 | F20: {=SUM('flock performance sheet'!J241:J247+'flock performance sheet'!K241:K247)} -> 0 | G20: =(F20/B20%)/7 -> 0 | H20: =F20/B4 -> 0 | I20: =I19+H20 -> 0.50593333
A21: 36 | B21: =B20-C20 -> 29778 | C21: {=SUM('flock performance sheet'!F248:F254+'flock performance sheet'!G248:G254)} -> 0 | D21: =C21/B21% -> 0 | E21: =E20+D21 -> 0.74 | F21: {=SUM('flock performance sheet'!J248:J254+'flock performance sheet'!K248:K254)} -> 0 | G21: =(F21/B21%)/7 -> 0 | H21: =F21/B4 -> 0 | I21: =I20+H21 -> 0.50593333
A22: 37 | B22: =B21-C21 -> 29778 | C22: {=SUM('flock performance sheet'!F255:F261+'flock performance sheet'!G255:G261)} -> 0 | D22: =C22/B22% -> 0 | E22: =E21+D22 -> 0.74 | F22: {=SUM('flock performance sheet'!J255:J261+'flock performance sheet'!K255:K261)} -> 0 | G22: =(F22/B22%)/7 -> 0 | H22: =F22/B4 -> 0 | I22: =I21+H22 -> 0.50593333
A23: 38 | B23: =B22-C22 -> 29778 | C23: {=SUM('flock performance sheet'!F262:F268+'flock performance sheet'!G262:G268)} -> 0 | D23: =C23/B23% -> 0 | E23: =E22+D23 -> 0.74 | F23: {=SUM('flock performance sheet'!J262:J268+'flock performance sheet'!K262:K268)} -> 0 | G23: =(F23/B23%)/7 -> 0 | H23: =F23/B4 -> 0 | I23: =I22+H23 -> 0.50593333
A24: 39 | B24: =B23-C23 -> 29778 | C24: {=SUM('flock performance sheet'!F269:F275+'flock performance sheet'!G269:G275)} -> 0 | D24: =C24/B24% -> 0 | E24: =E23+D24 -> 0.74 | F24: {=SUM('flock performance sheet'!J269:J275+'flock performance sheet'!K269:K275)} -> 0 | G24: =(F24/B24%)/7 -> 0 | H24: =F24/B4 -> 0 | I24: =I23+H24 -> 0.50593333
A25: 40 | B25: =B24-C24 -> 29778 | C25: {=SUM('flock performance sheet'!F276:F282+'flock performance sheet'!G276:G282)} -> 0 | D25: =C25/B25% -> 0 | E25: =E24+D25 -> 0.74 | F25: {=SUM('flock performance sheet'!J276:J282+'flock performance sheet'!K276:K282)} -> 0 | G25: =(F25/B25%)/7 -> 0 | H25: =F25/B4 -> 0 | I25: =I24+H25 -> 0.50593333
A26: 41 | B26: =B25-C25 -> 29778 | C26: {=SUM('flock performance sheet'!F283:F289+'flock performance sheet'!G283:G289)} -> 0 | D26: =C26/B26% -> 0 | E26: =E25+D26 -> 0.74 | F26: {=SUM('flock performance sheet'!J283:J289+'flock performance sheet'!K283:K289)} -> 0 | G26: =(F26/B26%)/7 -> 0 | H26: =F26/B4 -> 0 | I26: =I25+H26 -> 0.50593333
A27: 42 | B27: =B26-C26 -> 29778 | C27: {=SUM('flock performance sheet'!F290:F296+'flock performance sheet'!G290:G296)} -> 0 | D27: =C27/B27% -> 0 | E27: =E26+D27 -> 0.74 | F27: {=SUM('flock performance sheet'!J290:J296+'flock performance sheet'!K290:K296)} -> 0 | G27: =(F27/B27%)/7 -> 0 | H27: =F27/B4 -> 0 | I27: =I26+H27 -> 0.50593333
A28: 43 | B28: =B27-C27 -> 29778 | C28: {=SUM('flock performance sheet'!F297:F303+'flock performance sheet'!G297:G303)} -> 0 | D28: =C28/B28% -> 0 | E28: =E27+D28 -> 0.74 | F28: {=SUM('flock performance sheet'!J297:J303+'flock performance sheet'!K297:K303)} -> 0 | G28: =(F28/B28%)/7 -> 0 | H28: =F28/B4 -> 0 | I28: =I27+H28 -> 0.50593333
A29: 44 | B29: =B28-C28 -> 29778 | C29: {=SUM('flock performance sheet'!F304:F310+'flock performance sheet'!G304:G310)} -> 0 | D29: =C29/B29% -> 0 | E29: =E28+D29 -> 0.74 | F29: {=SUM('flock performance sheet'!J304:J310+'flock performance sheet'!K304:K310)} -> 0 | G29: =(F29/B29%)/7 -> 0 | H29: =F29/B4 -> 0 | I29: =I28+H29 -> 0.50593333
A30: 45 | B30: =B29-C29 -> 29778 | C30: {=SUM('flock performance sheet'!F311:F317+'flock performance sheet'!G311:G317)} -> 0 | D30: =C30/B30% -> 0 | E30: =E29+D30 -> 0.74 | F30: {=SUM('flock performance sheet'!J311:J317+'flock performance sheet'!K311:K317)} -> 0 | G30: =(F30/B30%)/7 -> 0 | H30: =F30/B4 -> 0 | I30: =I29+H30 -> 0.50593333
A31: 46 | B31: =B30-C30 -> 29778 | C31: {=SUM('flock performance sheet'!F318:F324+'flock performance sheet'!G318:G324)} -> 0 | D31: =C31/B31% -> 0 | E31: =E30+D31 -> 0.74 | F31: {=SUM('flock performance sheet'!J318:J324+'flock performance sheet'!K318:K324)} -> 0 | G31: =(F31/B31%)/7 -> 0 | H31: =F31/B4 -> 0 | I31: =I30+H31 -> 0.50593333
A32: 47 | B32: =B31-C31 -> 29778 | C32: {=SUM('flock performance sheet'!F325:F331+'flock performance sheet'!G325:G331)} -> 0 | D32: =C32/B32% -> 0 | E32: =E31+D32 -> 0.74 | F32: {=SUM('flock performance sheet'!J325:J331+'flock performance sheet'!K325:K331)} -> 0 | G32: =(F32/B32%)/7 -> 0 | H32: =F32/B4 -> 0 | I32: =I31+H32 -> 0.50593333
A33: 48 | B33: =B32-C32 -> 29778 | C33: {=SUM('flock performance sheet'!F332:F338+'flock performance sheet'!G332:G338)} -> 0 | D33: =C33/B33% -> 0 | E33: =E32+D33 -> 0.74 | F33: {=SUM('flock performance sheet'!J332:J338+'flock performance sheet'!K332:K338)} -> 0 | G33: =(F33/B33%)/7 -> 0 | H33: =F33/B4 -> 0 | I33: =I32+H33 -> 0.50593333
A34: 49 | B34: =B33-C33 -> 29778 | C34: {=SUM('flock performance sheet'!F339:F345+'flock performance sheet'!G339:G345)} -> 0 | D34: =C34/B34% -> 0 | E34: =E33+D34 -> 0.74 | F34: {=SUM('flock performance sheet'!J339:J345+'flock performance sheet'!K339:K345)} -> 0 | G34: =(F34/B34%)/7 -> 0 | H34: =F34/B4 -> 0 | I34: =I33+H34 -> 0.50593333
A35: 50 | B35: =B34-C34 -> 29778 | C35: {=SUM('flock performance sheet'!F346:F352+'flock performance sheet'!G346:G352)} -> 0 | D35: =C35/B35% -> 0 | E35: =E34+D35 -> 0.74 | F35: {=SUM('flock performance sheet'!J346:J352+'flock performance sheet'!K346:K352)} -> 0 | G35: =(F35/B35%)/7 -> 0 | H35: =F35/B4 -> 0 | I35: =I34+H35 -> 0.50593333
A36: 51 | B36: =B35-C35 -> 29778 | C36: {=SUM('flock performance sheet'!F353:F359+'flock performance sheet'!G353:G359)} -> 0 | D36: =C36/B36% -> 0 | E36: =E35+D36 -> 0.74 | F36: {=SUM('flock performance sheet'!J353:J359+'flock performance sheet'!K353:K359)} -> 0 | G36: =(F36/B36%)/7 -> 0 | H36: =F36/B4 -> 0 | I36: =I35+H36 -> 0.50593333
A37: 52 | B37: =B36-C36 -> 29778 | C37: {=SUM('flock performance sheet'!F360:F366+'flock performance sheet'!G360:G366)} -> 0 | D37: =C37/B37% -> 0 | E37: =E36+D37 -> 0.74 | F37: {=SUM('flock performance sheet'!J360:J366+'flock performance sheet'!K360:K366)} -> 0 | G37: =(F37/B37%)/7 -> 0 | H37: =F37/B4 -> 0 | I37: =I36+H37 -> 0.50593333
A38: 53 | B38: =B37-C37 -> 29778 | C38: {=SUM('flock performance sheet'!F367:F373+'flock performance sheet'!G367:G373)} -> 0 | D38: =C38/B38% -> 0 | E38: =E37+D38 -> 0.74 | F38: {=SUM('flock performance sheet'!J367:J373+'flock performance sheet'!K367:K373)} -> 0 | G38: =(F38/B38%)/7 -> 0 | H38: =F38/B4 -> 0 | I38: =I37+H38 -> 0.50593333
A39: 54 | B39: =B38-C38 -> 29778 | C39: {=SUM('flock performance sheet'!F374:F380+'flock performance sheet'!G374:G380)} -> 0 | D39: =C39/B39% -> 0 | E39: =E38+D39 -> 0.74 | F39: {=SUM('flock performance sheet'!J374:J380+'flock performance sheet'!K374:K380)} -> 0 | G39: =(F39/B39%)/7 -> 0 | H39: =F39/B4 -> 0 | I39: =I38+H39 -> 0.50593333
A40: 55 | B40: =B39-C39 -> 29778 | C40: {=SUM('flock performance sheet'!F381:F387+'flock performance sheet'!G381:G387)} -> 0 | D40: =C40/B40% -> 0 | E40: =E39+D40 -> 0.74 | F40: {=SUM('flock performance sheet'!J381:J387+'flock performance sheet'!K381:K387)} -> 0 | G40: =(F40/B40%)/7 -> 0 | H40: =F40/B4 -> 0 | I40: =I39+H40 -> 0.50593333
A41: 56 | B41: =B40-C40 -> 29778 | C41: {=SUM('flock performance sheet'!F388:F394+'flock performance sheet'!G388:G394)} -> 0 | D41: =C41/B41% -> 0 | E41: =E40+D41 -> 0.74 | F41: {=SUM('flock performance sheet'!J388:J394+'flock performance sheet'!K388:K394)} -> 0 | G41: =(F41/B41%)/7 -> 0 | H41: =F41/B4 -> 0 | I41: =I40+H41 -> 0.50593333
...

Sheet Sheet2

Sheet formula and explination
A1: FORMULA REGISTER
A2: Every formula cell in the workbook • 5,029 formulas inventoried
A3: Sheet | B3: Cell | C3: Column / Purpose | D3: Formula | E3: Current Result | F3: Explanation
A4: flock performance sheet | B4: C2 | C4: AGE OF THE BIRD | D4: =(QUOTIENT(ROW()-2,7)+1)&"."&MOD(ROW()-2,7)&" - day "&(MOD(ROW()-2,7)+1) | E4: 1.0 - day 1 | F4: Generates the bird-age week and day sequence automatically from the row number.
A5: flock performance sheet | B5: H2 | C5: BIRDS CLOSING STOCK | D5: =SUM(E2-F2-G2) | E5: 13668 | F5: Calculates closing stock as opening birds minus mortality and culls.
A6: flock performance sheet | B6: L2 | C6: ACTUAL PRODUCTION % | D6: =SUM(J2+K2)/H2*100 | E6: 91.308165 | F6: Calculates actual production percentage from eggs produced plus breakage, divided by closing bird stock.
A7: flock performance sheet | B7: N2 | C7: DIFFRENCE IN PRODUCTION | D7: =SUM(L2-M2) | E7: -1.8918349 | F7: Calculates production variance as actual production percentage minus target production.
A8: flock performance sheet | B8: O2 | C8: FEED PER BIRD | D8: =SUM(I2/H2)*1000 | E8: 118.52502 | F8: Calculates feed per bird from feed consumption and closing bird stock.
A9: flock performance sheet | B9: C3 | C9: AGE OF THE BIRD | D9: =(QUOTIENT(ROW()-2,7)+1)&"."&MOD(ROW()-2,7)&" - day "&(MOD(ROW()-2,7)+1) | E9: 1.1 - day 2 | F9: Generates the bird-age week and day sequence automatically from the row number.
A10: flock performance sheet | B10: H3 | C10: BIRDS CLOSING STOCK | D10: =SUM(E3-F3-G3) | E10: 13668 | F10: Calculates closing stock as opening birds minus mortality and culls.
A11: flock performance sheet | B11: L3 | C11: ACTUAL PRODUCTION % | D11: =SUM(J3+K3)/H3*100 | E11: 120.88821 | F11: Calculates actual production percentage from eggs produced plus breakage, divided by closing bird stock.
A12: flock performance sheet | B12: N3 | C12: DIFFRENCE IN PRODUCTION | D12: =SUM(L3-M3) | E12: 27.688206 | F12: Calculates production variance as actual production percentage minus target production.
A13: flock performance sheet | B13: O3 | C13: FEED PER BIRD | D13: =SUM(I3/H3)*1000 | E13: 82.089552 | F13: Calculates feed per bird from feed consumption and closing bird stock.
A14: flock performance sheet | B14: C4 | C14: AGE OF THE BIRD | D14: =(QUOTIENT(ROW()-2,7)+1)&"."&MOD(ROW()-2,7)&" - day "&(MOD(ROW()-2,7)+1) | E14: 1.2 - day 3 | F14: Generates the bird-age week and day sequence automatically from the row number.
A15: flock performance sheet | B15: E4 | C15: BIRDS OPENING STOCK | D15: =H3 | E15: 13668 | F15: Carries forward the previous closing bird stock as the next opening stock.
A16: flock performance sheet | B16: H4 | C16: BIRDS CLOSING STOCK | D16: =SUM(E4-F4-G4) | E16: 13658 | F16: Calculates closing stock as opening birds minus mortality and culls.
A17: flock performance sheet | B17: L4 | C17: ACTUAL PRODUCTION % | D17: =SUM(J4+K4)/H4*100 | E17: 98.879777 | F17: Calculates actual production percentage from eggs produced plus breakage, divided by closing bird stock.
A18: flock performance sheet | B18: N4 | C18: DIFFRENCE IN PRODUCTION | D18: =SUM(L4-M4) | E18: 5.6797774 | F18: Calculates production variance as actual production percentage minus target production.
A19: flock performance sheet | B19: O4 | C19: FEED PER BIRD | D19: =SUM(I4/H4)*1000 | E19: 118.6118 | F19: Calculates feed per bird from feed consumption and closing bird stock.
A20: flock performance sheet | B20: C5 | C20: AGE OF THE BIRD | D20: =(QUOTIENT(ROW()-2,7)+1)&"."&MOD(ROW()-2,7)&" - day "&(MOD(ROW()-2,7)+1) | E20: 1.3 - day 4 | F20: Generates the bird-age week and day sequence automatically from the row number.
A21: flock performance sheet | B21: E5 | C21: BIRDS OPENING STOCK | D21: =H4 | E21: 13658 | F21: Carries forward the previous closing bird stock as the next opening stock.
A22: flock performance sheet | B22: H5 | C22: BIRDS CLOSING STOCK | D22: =SUM(E5-F5-G5) | E22: 13658 | F22: Calculates closing stock as opening birds minus mortality and culls.
A23: flock performance sheet | B23: L5 | C23: ACTUAL PRODUCTION % | D23: =SUM(J5+K5)/H5*100 | E23: 0 | F23: Calculates actual production percentage from eggs produced plus breakage, divided by closing bird stock.
A24: flock performance sheet | B24: N5 | C24: DIFFRENCE IN PRODUCTION | D24: =SUM(L5-M5) | E24: -93.2 | F24: Calculates production variance as actual production percentage minus target production.
A25: flock performance sheet | B25: O5 | C25: FEED PER BIRD | D25: =SUM(I5/H5)*1000 | E25: 0 | F25: Calculates feed per bird from feed consumption and closing bird stock.
A26: flock performance sheet | B26: C6 | C26: AGE OF THE BIRD | D26: =(QUOTIENT(ROW()-2,7)+1)&"."&MOD(ROW()-2,7)&" - day "&(MOD(ROW()-2,7)+1) | E26: 1.4 - day 5 | F26: Generates the bird-age week and day sequence automatically from the row number.
A27: flock performance sheet | B27: E6 | C27: BIRDS OPENING STOCK | D27: =H5 | E27: 13658 | F27: Carries forward the previous closing bird stock as the next opening stock.
A28: flock performance sheet | B28: H6 | C28: BIRDS CLOSING STOCK | D28: =SUM(E6-F6-G6) | E28: 13658 | F28: Calculates closing stock as opening birds minus mortality and culls.
A29: flock performance sheet | B29: L6 | C29: ACTUAL PRODUCTION % | D29: =SUM(J6+K6)/H6*100 | E29: 0 | F29: Calculates actual production percentage from eggs produced plus breakage, divided by closing bird stock.
A30: flock performance sheet | B30: N6 | C30: DIFFRENCE IN PRODUCTION | D30: =SUM(L6-M6) | E30: -93.2 | F30: Calculates production variance as actual production percentage minus target production.
A31: flock performance sheet | B31: O6 | C31: FEED PER BIRD | D31: =SUM(I6/H6)*1000 | E31: 0 | F31: Calculates feed per bird from feed consumption and closing bird stock.
A32: flock performance sheet | B32: C7 | C32: AGE OF THE BIRD | D32: =(QUOTIENT(ROW()-2,7)+1)&"."&MOD(ROW()-2,7)&" - day "&(MOD(ROW()-2,7)+1) | E32: 1.5 - day 6 | F32: Generates the bird-age week and day sequence automatically from the row number.
A33: flock performance sheet | B33: E7 | C33: BIRDS OPENING STOCK | D33: =H6 | E33: 13658 | F33: Carries forward the previous closing bird stock as the next opening stock.
A34: flock performance sheet | B34: H7 | C34: BIRDS CLOSING STOCK | D34: =SUM(E7-F7-G7) | E34: 13658 | F34: Calculates closing stock as opening birds minus mortality and culls.
A35: flock performance sheet | B35: L7 | C35: ACTUAL PRODUCTION % | D35: =SUM(J7+K7)/H7*100 | E35: 0 | F35: Calculates actual production percentage from eggs produced plus breakage, divided by closing bird stock.
A36: flock performance sheet | B36: N7 | C36: DIFFRENCE IN PRODUCTION | D36: =SUM(L7-M7) | E36: -93.2 | F36: Calculates production variance as actual production percentage minus target production.
A37: flock performance sheet | B37: O7 | C37: FEED PER BIRD | D37: =SUM(I7/H7)*1000 | E37: 0 | F37: Calculates feed per bird from feed consumption and closing bird stock.
A38: flock performance sheet | B38: C8 | C38: AGE OF THE BIRD | D38: =(QUOTIENT(ROW()-2,7)+1)&"."&MOD(ROW()-2,7)&" - day "&(MOD(ROW()-2,7)+1) | E38: 1.6 - day 7 | F38: Generates the bird-age week and day sequence automatically from the row number.
A39: flock performance sheet | B39: E8 | C39: BIRDS OPENING STOCK | D39: =H7 | E39: 13658 | F39: Carries forward the previous closing bird stock as the next opening stock.
A40: flock performance sheet | B40: H8 | C40: BIRDS CLOSING STOCK | D40: =SUM(E8-F8-G8) | E40: 13658 | F40: Calculates closing stock as opening birds minus mortality and culls.
...
